<?xml version="1.0" ?>
<!-- 
  This is not a standalone urdf for zerg. It simply defines the 'zerg' tag that can
  be incorporated by other urdf files (e.g. zerg).
 -->
<robot name="zerg_base" xmlns:xacro="http://ros.org/wiki/xacro">
  <include filename="$(find turtlebot_description)/urdf/common_properties.urdf.xacro"/>

  <!-- Xacro properties -->
  <xacro:property name="M_SCALE" value="0.001"/>

  <xacro:macro name="zerg_wheel" params="link_name">
      <link name="${link_name}">
      <visual>
        <geometry>
            <!--mesh filename="package://kobuki_description/meshes/wheel.dae"/-->
            <cylinder radius="0.0635" length="0.04"/>
        </geometry>
        <xacro:insert_block name="material_dark_grey"/>
        <origin xyz="0 0 0.0" rpy="0 0 0"/>
      </visual>
      <collision>
        <geometry>
          <cylinder radius="0.0635" length="0.04"/>
        </geometry>
        <origin rpy="0 0 0" xyz="0 0 0"/>
      </collision>
      <inertial>
        <mass value="0.1" />
        <origin xyz="0 0 0" />        
        <inertia ixx="0.001" ixy="0.0" ixz="0.0"
                 iyy="0.001" iyz="0.0" 
                 izz="0.001" />
      </inertial>
    </link>
  </xacro:macro>

  <!-- Kobuki --> 
  <xacro:macro name="zerg_base">   
    <link name="base_footprint"/>
    <!--
       Base link is set at the ground.
      -->
    <joint name="base_joint" type="fixed">
      <origin xyz="0 0 0.0" rpy="0 0 0" />
      <parent link="base_footprint"/>
      <child link="base_link" />
    </joint>
    <link name="base_link">
      <visual>
        <geometry>
          <!-- new mesh -->
          <!--mesh filename="package://kobuki_description/meshes/main_body.dae" /-->
          <box size="0.357 0.357 0.097"/>
        </geometry>
        <xacro:insert_block name="material_light_grey"/>
        <origin xyz="0.0 0 0.0895" rpy="0 0 0"/> <!-- 4.1cm above ground + 9.7cm height / 2 -->
      </visual>
      <collision>
        <geometry>
          <box size="0.357 0.357 0.097"/>
        </geometry>
        <origin xyz="0.0 0 0.0895" rpy="0 0 0"/>
      </collision>
      <inertial>
        <mass value="5.0"/>
        <origin xyz="0 0 0.0895"/>
        <inertia ixx="0.0001" ixy="0.0" ixz="0.0"
                 iyy="0.0001" iyz="0.0" 
                 izz="0.0001" />
      </inertial>
    </link>
    
    <zerg_wheel link_name="wheel_front_left_link" />
    <zerg_wheel link_name="wheel_front_right_link" />
    <zerg_wheel link_name="wheel_rear_left_link" />
    <zerg_wheel link_name="wheel_rear_right_link" />

    <joint name="wheel_front_left_joint" type="continuous">
      <parent link="base_link"/>
      <child link="wheel_front_left_link"/>
      <origin xyz="0.134 ${0.357/2 + 0.02} 0.0635" rpy="${-M_PI/2} 0 0"/>
      <axis xyz="0 0 1"/>
    </joint>
    <joint name="wheel_front_right_joint" type="continuous">
      <parent link="base_link"/>
      <child link="wheel_front_right_link"/>
      <origin xyz="0.134 -${0.357/2 + 0.02} 0.0635" rpy="${-M_PI/2} 0 0"/>
      <axis xyz="0 0 1"/>
    </joint>
    <joint name="wheel_rear_left_joint" type="continuous">
      <parent link="base_link"/>
      <child link="wheel_rear_left_link"/>
      <origin xyz="-0.134 ${0.357/2 + 0.02} 0.0635" rpy="${-M_PI/2} 0 0"/>
      <axis xyz="0 0 1"/>
    </joint>
    <joint name="wheel_rear_right_joint" type="continuous">
      <parent link="base_link"/>
      <child link="wheel_rear_right_link"/>
      <origin xyz="-0.134 -${0.357/2 + 0.02} 0.0635" rpy="${-M_PI/2} 0 0"/>
      <axis xyz="0 0 1"/>
    </joint>

  </xacro:macro>
</robot>
